<?xml version="1.0" ?>
<!-- =================================================================================== -->
<!-- |    This document was autogenerated by xacro from x1_from_sdf.xacro              | -->
<!-- |    EDITING THIS FILE BY HAND IS NOT RECOMMENDED                                 | -->
<!-- =================================================================================== -->
<robot name="X1">
  <link name="X1/base_link">
    <!--<inertial>
      <origin xyz='-0.00065 -0.085 0.062' rpy='0 -0 0'/>
      <mass value='46.034'/>
      <inertia ixx='0.613201' ixy='-0.0236401' ixz='-0.1197' iyy='1.7496' iyz='-0.00154411' izz='2.0406'/>
    </inertial>-->
    <collision name="base_collision">
      <origin rpy="0 -0 0" xyz="0 0 0.061875"/>
      <geometry>
        <box size="0.9874 0.5709 0.12375"/>
      </geometry>
    </collision>
    <collision name="base_collision_1">
      <origin rpy="0 -0 0" xyz="0 0 0.185625"/>
      <geometry>
        <box size="0.78992 0.5709 0.12375"/>
      </geometry>
    </collision>
    <collision name="top_plate_collision">
      <origin rpy="0 -0 0" xyz="0.0812 0 0.245"/>
      <geometry>
        <mesh filename="package://x1_description/meshes/top_plate.dae" scale="1 1 1"/>
      </geometry>
    </collision>
    <collision name="top_plate_collision_2">
      <origin rpy="0 -0 0" xyz="0.0812 0 0.245"/>
      <geometry>
        <box size="0.32 0.41 0.09"/>
      </geometry>
    </collision>
    <visual name="base_visual">
      <origin rpy="0 0 -3.14159" xyz="0 0 0"/>
      <geometry>
        <mesh filename="package://x1_description/meshes/chassis.dae" scale="1 1 1"/>
      </geometry>
    </visual>
    <visual name="center_left_headlight_visual">
      <origin rpy="0 0 -3.14159" xyz="0.485766 0.0844 0.124431"/>
      <geometry>
        <mesh filename="package://x1_description/meshes/headlight.dae" scale="1 1 1"/>
      </geometry>
    </visual>
    <visual name="center_right_headlight_visual">
      <origin rpy="0 0 -3.14159" xyz="0.485766 -0.0844 0.124431"/>
      <geometry>
        <mesh filename="package://x1_description/meshes/headlight.dae" scale="1 1 1"/>
      </geometry>
    </visual>
    <visual name="left_headlight_visual">
      <origin rpy="0 0 -3.14159" xyz="0.461459 0.216803 0.124431"/>
      <geometry>
        <mesh filename="package://x1_description/meshes/headlight.dae" scale="1 1 1"/>
      </geometry>
    </visual>
    <visual name="marker_visual_1">
      <origin rpy="-3.14159 1.57079 -1.60259" xyz="0.066047 0.212211 0.209188"/>
      <geometry>
        <mesh filename="package://x1_description/meshes/led.dae" scale="1 1 1"/>
      </geometry>
    </visual>
    <visual name="marker_visual_2">
      <origin rpy="-3.14159 1.57079 -1.60259" xyz="-0.066047 0.212211 0.209188"/>
      <geometry>
        <mesh filename="package://x1_description/meshes/led.dae" scale="1 1 1"/>
      </geometry>
    </visual>
    <visual name="marker_visual_3">
      <origin rpy="3.14159 1.57079 7e-06" xyz="-0.42493 0 0.209188"/>
      <geometry>
        <mesh filename="package://x1_description/meshes/led.dae" scale="1 1 1"/>
      </geometry>
    </visual>
    <visual name="marker_visual_4">
      <origin rpy="3.14159 1.57079 7e-06" xyz="-0.42493 0.13619 0.209188"/>
      <geometry>
        <mesh filename="package://x1_description/meshes/led.dae" scale="1 1 1"/>
      </geometry>
    </visual>
    <visual name="marker_visual_5">
      <origin rpy="3.14159 1.57079 7e-06" xyz="-0.42493 -0.13619 0.209188"/>
      <geometry>
        <mesh filename="package://x1_description/meshes/led.dae" scale="1 1 1"/>
      </geometry>
    </visual>
    <visual name="right_headlight_visual">
      <origin rpy="0 0 -3.14159" xyz="0.461459 -0.216803 0.124431"/>
      <geometry>
        <mesh filename="package://x1_description/meshes/headlight.dae" scale="1 1 1"/>
      </geometry>
    </visual>
    <visual name="marker_visual_6">
      <origin rpy="3.14159 1.57079 1.60259" xyz="0.066047 -0.212211 0.209188"/>
      <geometry>
        <mesh filename="package://x1_description/meshes/led.dae" scale="1 1 1"/>
      </geometry>
    </visual>
    <visual name="marker_visual_7">
      <origin rpy="3.14159 1.57079 1.60259" xyz="-0.066047 -0.212211 0.209188"/>
      <geometry>
        <mesh filename="package://x1_description/meshes/led.dae" scale="1 1 1"/>
      </geometry>
    </visual>
    <visual name="top_plate_visual">
      <origin rpy="0 -0 0" xyz="0.0812 0 0.245"/>
      <geometry>
        <mesh filename="package://x1_description/meshes/top_plate.dae" scale="1 1 1"/>
      </geometry>
    </visual>
    <visual name="left_light_source">
      <origin rpy="3.14159 -3e-06 3.14159" xyz="0.435959 0.124431 0"/>
      <geometry>
        <mesh filename="package://x1_description/meshes/headlight_lamp.dae" scale="1 1 1"/>
      </geometry>
    </visual>
    <visual name="center_left_light_visual">
      <origin rpy="0 0 -3.14159" xyz="0.485266 0.0844 0.124431"/>
      <geometry>
        <mesh filename="package://x1_description/meshes/headlight_lamp.dae" scale="1 1 1"/>
      </geometry>
    </visual>
  </link>
  <sensor name="imu_sensor" update_rate="1000">
    <parent link="X1/base_link"/>
    <origin rpy="0 -0 0" xyz="0 0 0"/>
  </sensor>
  <link name="X1/front_left_wheel">
    <inertial>
      <origin rpy="0 -0 0" xyz="0 0 0"/>
      <mass value="2.637"/>
      <inertia ixx="0.02467" ixy="0" ixz="0" iyy="0.04411" iyz="0" izz="0.02467"/>
    </inertial>
    <collision name="collision">
      <origin rpy="-1.57079 0 0" xyz="0 0 0"/>
      <geometry>
        <cylinder length="0.1143" radius="0.1651"/>
      </geometry>
    </collision>
    <visual name="visual">
      <origin rpy="0 -0 0" xyz="0 0 0"/>
      <geometry>
        <mesh filename="package://x1_description/meshes/wheel.dae" scale="1 1 1"/>
      </geometry>
    </visual>
  </link>
  <link name="X1/front_right_wheel">
    <inertial>
      <origin rpy="0 -0 0" xyz="0 0 0"/>
      <mass value="2.637"/>
      <inertia ixx="0.02467" ixy="0" ixz="0" iyy="0.04411" iyz="0" izz="0.02467"/>
    </inertial>
    <collision name="collision">
      <origin rpy="-1.57079 0 0" xyz="0 0 0"/>
      <geometry>
        <cylinder length="0.1143" radius="0.1651"/>
      </geometry>
    </collision>
    <visual name="visual">
      <origin rpy="0 -0 0" xyz="0 0 0"/>
      <geometry>
        <mesh filename="package://x1_description/meshes/wheel.dae" scale="1 1 1"/>
      </geometry>
    </visual>
  </link>
  <link name="X1/rear_left_wheel">
    <inertial>
      <origin rpy="0 -0 0" xyz="0 0 0"/>
      <mass value="2.637"/>
      <inertia ixx="0.02467" ixy="0" ixz="0" iyy="0.04411" iyz="0" izz="0.02467"/>
    </inertial>
    <collision name="collision">
      <origin rpy="-1.57079 0 0" xyz="0 0 0"/>
      <geometry>
        <cylinder length="0.1143" radius="0.1651"/>
      </geometry>
    </collision>
    <visual name="visual">
      <origin rpy="0 -0 0" xyz="0 0 0"/>
      <geometry>
        <mesh filename="package://x1_description/meshes/wheel.dae" scale="1 1 1"/>
      </geometry>
    </visual>
  </link>
  <link name="X1/rear_right_wheel">
    <inertial>
      <origin rpy="0 -0 0" xyz="0 0 0"/>
      <mass value="2.637"/>
      <inertia ixx="0.02467" ixy="0" ixz="0" iyy="0.04411" iyz="0" izz="0.02467"/>
    </inertial>
    <collision name="collision">
      <origin rpy="-1.57079 0 0" xyz="0 0 0"/>
      <geometry>
        <cylinder length="0.1143" radius="0.1651"/>
      </geometry>
    </collision>
    <visual name="visual">
      <origin rpy="0 -0 0" xyz="0 0 0"/>
      <geometry>
        <mesh filename="package://x1_description/meshes/wheel.dae" scale="1 1 1"/>
      </geometry>
    </visual>
  </link>
  <link name="X1/base_footprint"/>
  <joint name="base_joint" type="fixed">
    <parent link="X1/base_link"/>
    <child link="X1/base_footprint"/>
    <origin rpy="0 0 0" xyz="0.0 0.0 0"/>
    <!-- Set footprint at the projection of the center of the main chassis (z in ground) -->
  </joint>
  <joint name="front_left_wheel_joint" type="revolute">
    <origin rpy="0 -0 0" xyz="0.256 0.2854 0.03282"/>
    <parent link="X1/base_link"/>
    <child link="X1/front_left_wheel"/>
    <axis xyz="0 1 0"/>
    <limit effort="-1" lower="-1.79769e+308" upper="1.79769e+308" velocity="-1"/>
  </joint>
  <joint name="front_right_wheel_joint" type="revolute">
    <origin rpy="0 -0 0" xyz="0.256 -0.2854 0.03282"/>
    <parent link="X1/base_link"/>
    <child link="X1/front_right_wheel"/>
    <axis xyz="0 1 0"/>
    <limit effort="-1" lower="-1.79769e+308" upper="1.79769e+308" velocity="-1"/>
  </joint>
  <joint name="rear_left_wheel_joint" type="revolute">
    <origin rpy="0 -0 0" xyz="-0.256 0.2854 0.03282"/>
    <parent link="X1/base_link"/>
    <child link="X1/rear_left_wheel"/>
    <axis xyz="0 1 0"/>
    <limit effort="-1" lower="-1.79769e+308" upper="1.79769e+308" velocity="-1"/>
  </joint>
  <joint name="rear_right_wheel_joint" type="revolute">
    <origin rpy="0 -0 0" xyz="-0.256 -0.2854 0.03282"/>
    <parent link="X1/base_link"/>
    <child link="X1/rear_right_wheel"/>
    <axis xyz="0 1 0"/>
    <limit effort="-1" lower="-1.79769e+308" upper="1.79769e+308" velocity="-1"/>
  </joint>
</robot>
