<?xml version="1.0" ?>
<!-- =================================================================================== -->
<!-- |    This document was autogenerated by xacro from rm2.urdf.xacro                 | -->
<!-- |    EDITING THIS FILE BY HAND IS NOT RECOMMENDED                                 | -->
<!-- =================================================================================== -->
<robot name="rm2_sim">
  <gazebo>
    <!-- DIFFERENTIAL DRIVE -->
    <!--ign topic -t "/cmd_vel" -m ignition.msgs.Twist -p "linear: {x: 0.5}, angular: {z: 0.05}"-->
    <plugin filename="libignition-gazebo-diff-drive-system.so" name="ignition::gazebo::systems::DiffDrive">
      <left_joint>wa2_j_wb_fw</left_joint>
      <left_joint>wa2_j_wb_bw</left_joint>
      <right_joint>wa3_j_wb_fw</right_joint>
      <right_joint>wa3_j_wb_bw</right_joint>
      <wheel_separation>0.245</wheel_separation>
      <wheel_radius>0.030</wheel_radius>
      <odom_publish_frequency>1000</odom_publish_frequency>
      <topic>/cmd_vel</topic>
      <frame_id>odom</frame_id>
      <child_frame_id>base_link</child_frame_id>
    </plugin>
  </gazebo>
  <gazebo>
    <plugin filename="libignition-gazebo-joint-state-publisher-system.so" name="ignition::gazebo::systems::JointStatePublisher"/>
  </gazebo>
  <link name="base_link">
    <pose>0 0 0 0 0 0</pose>
    <inertial>
      <mass value="1.114"/>
      <inertia ixx="0.00773" ixy="0" ixz="0" iyy="0.00937" iyz="0" izz="0.00938"/>
    </inertial>
    <collision name="collision_base">
      <geometry>
        <mesh filename="file:///home/esther/robominers_ws/install/rm2_simulation/share/rm2_simulation/urdf/meshes/body_collision.stl" scale="0.001 0.001 0.001"/>
      </geometry>
    </collision>
    <visual name="visual_base">
      <geometry>
        <mesh filename="file:///home/esther/robominers_ws/install/rm2_simulation/share/rm2_simulation/urdf/meshes/body_structure_blue.dae"/>
      </geometry>
    </visual>
  </link>
  <!-- =================================================================================== -->
  <!-- |                                          LEGS                                   | -->
  <!-- =================================================================================== -->
  <!-- JOINT BODY - SIMPLE LEG 1 -->
  <joint name="j_b_l1" type="fixed">
    <origin rpy="0 0 0" xyz="0.083 0 0.075"/>
    <parent link="base_link"/>
    <child link="l1_lLink"/>
  </joint>
  <link name="l1_lLink">
    <inertial>
      <mass value="0.001"/>
      <inertia ixx="0.00012" ixy="0" ixz="0" iyy="0.00096" iyz="0" izz="0.00094"/>
    </inertial>
  </link>
  <!-- JOINT LEG - MOTORS -->
  <joint name="l1_j_l_m" type="fixed">
    <origin rpy="0 0 0" xyz="-0.0822 0 0.0105"/>
    <parent link="l1_lLink"/>
    <child link="l1_mLink"/>
  </joint>
  <!-- INCLUDE MOTORS-->
  <link name="l1_mLink">
    <inertial>
      <mass value="0.393"/>
      <inertia ixx="0.00012" ixy="0" ixz="0" iyy="0.00096" iyz="0" izz="0.00094"/>
    </inertial>
    <collision name="collision_base">
      <geometry>
        <mesh filename="file:///home/esther/robominers_ws/install/rm2_simulation/share/rm2_simulation/urdf/meshes/motors.stl" scale="0.001 0.001 0.001"/>
      </geometry>
    </collision>
    <visual name="visual_base">
      <geometry>
        <mesh filename="file:///home/esther/robominers_ws/install/rm2_simulation/share/rm2_simulation/urdf/meshes/motors.dae"/>
      </geometry>
    </visual>
  </link>
  <!-- JOINT MOTORS - FRAMES -->
  <joint name="l1_j_m_f" type="fixed">
    <origin rpy="0 0 0" xyz="0.0153 0.019 0.0135"/>
    <parent link="l1_mLink"/>
    <child link="l1_fLink"/>
  </joint>
  <!-- INCLUDE FRAMES -->
  <link name="l1_fLink">
    <inertial>
      <mass value="0.044"/>
      <inertia ixx="0.00007" ixy="0" ixz="0" iyy="0.00012" iyz="0" izz="0.00009"/>
    </inertial>
    <collision name="collision_base">
      <origin rpy="0 0 0" xyz="-0.0162 -0.019 0.0447"/>
      <geometry>
        <box size="0.13 0.047 0.096"/>
      </geometry>
    </collision>
    <visual name="visual_base">
      <origin rpy="0 0 0" xyz="-0.0162 -0.019 0.0447"/>
      <geometry>
        <mesh filename="file:///home/esther/robominers_ws/install/rm2_simulation/share/rm2_simulation/urdf/meshes/frames.dae"/>
      </geometry>
    </visual>
  </link>
  <!-- JOINT BODY - SIMPLE LEG 2 (LEFT)-->
  <joint name="j_b_l2" type="fixed">
    <origin rpy="-2.0944 0 0" xyz="0.083 0.065 -0.0375"/>
    <parent link="base_link"/>
    <child link="l2_lLink"/>
  </joint>
  <link name="l2_lLink">
    <inertial>
      <mass value="0.001"/>
      <inertia ixx="0.00012" ixy="0" ixz="0" iyy="0.00096" iyz="0" izz="0.00094"/>
    </inertial>
  </link>
  <!-- JOINT LEG - MOTORS -->
  <joint name="l2_j_l_m" type="fixed">
    <origin rpy="-0.523599 0 0" xyz="-0.0822 0 0.0105"/>
    <parent link="l2_lLink"/>
    <child link="l2_mLink"/>
  </joint>
  <!-- INCLUDE MOTORS-->
  <link name="l2_mLink">
    <inertial>
      <mass value="0.393"/>
      <inertia ixx="0.00012" ixy="0" ixz="0" iyy="0.00096" iyz="0" izz="0.00094"/>
    </inertial>
    <collision name="collision_base">
      <geometry>
        <mesh filename="file:///home/esther/robominers_ws/install/rm2_simulation/share/rm2_simulation/urdf/meshes/motors.stl" scale="0.001 0.001 0.001"/>
      </geometry>
    </collision>
    <visual name="visual_base">
      <geometry>
        <mesh filename="file:///home/esther/robominers_ws/install/rm2_simulation/share/rm2_simulation/urdf/meshes/motors.dae"/>
      </geometry>
    </visual>
  </link>
  <!-- JOINT MOTORS - FRAMES -->
  <joint name="l2_j_m_f" type="fixed">
    <origin rpy="0 0 0" xyz="0.0153 0.019 0.0135"/>
    <parent link="l2_mLink"/>
    <child link="l2_fLink"/>
  </joint>
  <!-- INCLUDE FRAMES -->
  <link name="l2_fLink">
    <inertial>
      <mass value="0.044"/>
      <inertia ixx="0.00007" ixy="0" ixz="0" iyy="0.00012" iyz="0" izz="0.00009"/>
    </inertial>
    <collision name="collision_base">
      <origin rpy="0 0 0" xyz="-0.0162 -0.019 0.0447"/>
      <geometry>
        <box size="0.13 0.047 0.096"/>
      </geometry>
    </collision>
    <visual name="visual_base">
      <origin rpy="0 0 0" xyz="-0.0162 -0.019 0.0447"/>
      <geometry>
        <mesh filename="file:///home/esther/robominers_ws/install/rm2_simulation/share/rm2_simulation/urdf/meshes/frames.dae"/>
      </geometry>
    </visual>
  </link>
  <!-- JOINT BODY - SIMPLE LEG 3 (RIGHT)-->
  <joint name="j_b_l3" type="fixed">
    <origin rpy="2.0944 0 0" xyz="0.083 -0.065 -0.0375"/>
    <parent link="base_link"/>
    <child link="l3_lLink"/>
  </joint>
  <link name="l3_lLink">
    <inertial>
      <mass value="0.001"/>
      <inertia ixx="0.00012" ixy="0" ixz="0" iyy="0.00096" iyz="0" izz="0.00094"/>
    </inertial>
  </link>
  <!-- JOINT LEG - MOTORS -->
  <joint name="l3_j_l_m" type="fixed">
    <origin rpy="0.523599 0 0" xyz="-0.0822 0 0.0105"/>
    <parent link="l3_lLink"/>
    <child link="l3_mLink"/>
  </joint>
  <!-- INCLUDE MOTORS-->
  <link name="l3_mLink">
    <inertial>
      <mass value="0.393"/>
      <inertia ixx="0.00012" ixy="0" ixz="0" iyy="0.00096" iyz="0" izz="0.00094"/>
    </inertial>
    <collision name="collision_base">
      <geometry>
        <mesh filename="file:///home/esther/robominers_ws/install/rm2_simulation/share/rm2_simulation/urdf/meshes/motors.stl" scale="0.001 0.001 0.001"/>
      </geometry>
    </collision>
    <visual name="visual_base">
      <geometry>
        <mesh filename="file:///home/esther/robominers_ws/install/rm2_simulation/share/rm2_simulation/urdf/meshes/motors.dae"/>
      </geometry>
    </visual>
  </link>
  <!-- JOINT MOTORS - FRAMES -->
  <joint name="l3_j_m_f" type="fixed">
    <origin rpy="0 0 0" xyz="0.0153 0.019 0.0135"/>
    <parent link="l3_mLink"/>
    <child link="l3_fLink"/>
  </joint>
  <!-- INCLUDE FRAMES -->
  <link name="l3_fLink">
    <inertial>
      <mass value="0.044"/>
      <inertia ixx="0.00007" ixy="0" ixz="0" iyy="0.00012" iyz="0" izz="0.00009"/>
    </inertial>
    <collision name="collision_base">
      <origin rpy="0 0 0" xyz="-0.0162 -0.019 0.0447"/>
      <geometry>
        <box size="0.13 0.047 0.096"/>
      </geometry>
    </collision>
    <visual name="visual_base">
      <origin rpy="0 0 0" xyz="-0.0162 -0.019 0.0447"/>
      <geometry>
        <mesh filename="file:///home/esther/robominers_ws/install/rm2_simulation/share/rm2_simulation/urdf/meshes/frames.dae"/>
      </geometry>
    </visual>
  </link>
  <!-- =================================================================================== -->
  <!-- |                                      ACTUATORS                                  | -->
  <!-- =================================================================================== -->
  <link name="sa1_aLink">
    <inertial>
      <mass value="0.001"/>
      <inertia ixx="0.00012" ixy="0" ixz="0" iyy="0.00096" iyz="0" izz="0.00094"/>
    </inertial>
  </link>
  <!-- JOINT ACTUATOR - SCREW BASE -->
  <joint name="sa1_j_a_sb" type="fixed">
    <origin rpy="0 0 0" xyz="-0.0045 -0.024 0.0107"/>
    <parent link="sa1_aLink"/>
    <child link="sa1_sbLink"/>
  </joint>
  <!-- INCLUDE SCREW BASE -->
  <link name="sa1_sbLink">
    <inertial>
      <mass value="0.2"/>
      <inertia ixx="0.064" ixy="0" ixz="0" iyy="0.064" iyz="0" izz="0.00024"/>
    </inertial>
    <!-- <collision name='collision_base'>
        <geometry>
            <cylinder>
                <radius>0.010</radius>
                <length>0.050</length>
              </cylinder>
        </geometry>
      </collision> -->
    <visual name="visual_base">
      <geometry>
        <mesh filename="file:///home/esther/robominers_ws/install/rm2_simulation/share/rm2_simulation/urdf/meshes/screw_base.dae"/>
      </geometry>
    </visual>
  </link>
  <!-- JOINT SCREW BASE - CW SCREW -->
  <joint name="sa1_j_sb_cws" type="continuous">
    <origin rpy="0 1.5708 0" xyz="0.010 0 0.0025"/>
    <parent link="sa1_sbLink"/>
    <child link="sa1_cwsLink"/>
    <axis rpy="0 0 0" xyz="0 0 1"/>
    <limit effort="500" velocity="3.141592653589793"/>
  </joint>
  <!-- INCLUDE CW SCREW -->
  <link name="sa1_cwsLink">
    <inertial>
      <mass value="0.2"/>
      <inertia ixx="0.064" ixy="0" ixz="0" iyy="0.064" iyz="0" izz="0.00024"/>
    </inertial>
    <!-- <collision name='collision_base'>
      <geometry>
          <cylinder>
              <radius>0.010</radius>
              <length>0.050</length>
            </cylinder>
      </geometry>
    </collision> -->
    <visual name="visual_base">
      <origin rpy="0 0 0" xyz="0.0 0.0 0.0406"/>
      <geometry>
        <mesh filename="file:///home/esther/robominers_ws/install/rm2_simulation/share/rm2_simulation/urdf/meshes/forward_screw.dae"/>
      </geometry>
    </visual>
  </link>
  <!-- JOINT SCREW BASE - CCW SCREW -->
  <joint name="sa1_j_sb_ccws" type="continuous">
    <origin rpy="0 -1.5708 0" xyz="-0.010 0 0.0025"/>
    <parent link="sa1_sbLink"/>
    <child link="sa1_ccwsLink"/>
    <axis rpy="0 0 0" xyz="0 0 1"/>
    <limit effort="500" velocity="3.141592653589793"/>
  </joint>
  <link name="sa1_ccwsLink">
    <inertial>
      <mass value="0.2"/>
      <inertia ixx="0.064" ixy="0" ixz="0" iyy="0.064" iyz="0" izz="0.00024"/>
    </inertial>
    <!-- <collision name='collision_base'>
          <geometry>
              <cylinder>
                  <radius>0.010</radius>
                  <length>0.050</length>
                </cylinder>
          </geometry>
        </collision> -->
    <visual name="visual_base">
      <origin rpy="0 0 0" xyz="0.0 0.0 0.0406"/>
      <geometry>
        <mesh filename="file:///home/esther/robominers_ws/install/rm2_simulation/share/rm2_simulation/urdf/meshes/backward_screw.dae"/>
      </geometry>
    </visual>
  </link>
  <!-- JOINT SIMPLE LEG 1 - SCREW ACTUATOR -->
  <joint name="j_l1_sa1" type="fixed">
    <origin rpy="0 0 0" xyz="-0.0127 0.005 0.092"/>
    <parent link="l1_fLink"/>
    <child link="sa1_aLink"/>
  </joint>
  <link name="sa2_aLink">
    <inertial>
      <mass value="0.001"/>
      <inertia ixx="0.00012" ixy="0" ixz="0" iyy="0.00096" iyz="0" izz="0.00094"/>
    </inertial>
  </link>
  <!-- JOINT ACTUATOR - SCREW BASE -->
  <joint name="sa2_j_a_sb" type="fixed">
    <origin rpy="0 0 0" xyz="-0.0045 -0.024 0.0107"/>
    <parent link="sa2_aLink"/>
    <child link="sa2_sbLink"/>
  </joint>
  <!-- INCLUDE SCREW BASE -->
  <link name="sa2_sbLink">
    <inertial>
      <mass value="0.2"/>
      <inertia ixx="0.064" ixy="0" ixz="0" iyy="0.064" iyz="0" izz="0.00024"/>
    </inertial>
    <!-- <collision name='collision_base'>
        <geometry>
            <cylinder>
                <radius>0.010</radius>
                <length>0.050</length>
              </cylinder>
        </geometry>
      </collision> -->
    <visual name="visual_base">
      <geometry>
        <mesh filename="file:///home/esther/robominers_ws/install/rm2_simulation/share/rm2_simulation/urdf/meshes/screw_base.dae"/>
      </geometry>
    </visual>
  </link>
  <!-- JOINT SCREW BASE - CW SCREW -->
  <joint name="sa2_j_sb_cws" type="continuous">
    <origin rpy="0 1.5708 0" xyz="0.010 0 0.0025"/>
    <parent link="sa2_sbLink"/>
    <child link="sa2_cwsLink"/>
    <axis rpy="0 0 0" xyz="0 0 1"/>
    <limit effort="500" velocity="3.141592653589793"/>
  </joint>
  <!-- INCLUDE CW SCREW -->
  <link name="sa2_cwsLink">
    <inertial>
      <mass value="0.2"/>
      <inertia ixx="0.064" ixy="0" ixz="0" iyy="0.064" iyz="0" izz="0.00024"/>
    </inertial>
    <!-- <collision name='collision_base'>
      <geometry>
          <cylinder>
              <radius>0.010</radius>
              <length>0.050</length>
            </cylinder>
      </geometry>
    </collision> -->
    <visual name="visual_base">
      <origin rpy="0 0 0" xyz="0.0 0.0 0.0406"/>
      <geometry>
        <mesh filename="file:///home/esther/robominers_ws/install/rm2_simulation/share/rm2_simulation/urdf/meshes/forward_screw.dae"/>
      </geometry>
    </visual>
  </link>
  <!-- JOINT SCREW BASE - CCW SCREW -->
  <joint name="sa2_j_sb_ccws" type="continuous">
    <origin rpy="0 -1.5708 0" xyz="-0.010 0 0.0025"/>
    <parent link="sa2_sbLink"/>
    <child link="sa2_ccwsLink"/>
    <axis rpy="0 0 0" xyz="0 0 1"/>
    <limit effort="500" velocity="3.141592653589793"/>
  </joint>
  <link name="sa2_ccwsLink">
    <inertial>
      <mass value="0.2"/>
      <inertia ixx="0.064" ixy="0" ixz="0" iyy="0.064" iyz="0" izz="0.00024"/>
    </inertial>
    <!-- <collision name='collision_base'>
          <geometry>
              <cylinder>
                  <radius>0.010</radius>
                  <length>0.050</length>
                </cylinder>
          </geometry>
        </collision> -->
    <visual name="visual_base">
      <origin rpy="0 0 0" xyz="0.0 0.0 0.0406"/>
      <geometry>
        <mesh filename="file:///home/esther/robominers_ws/install/rm2_simulation/share/rm2_simulation/urdf/meshes/backward_screw.dae"/>
      </geometry>
    </visual>
  </link>
  <!-- JOINT SIMPLE LEG 2 - SCREW ACTUATOR -->
  <joint name="j_l1_sa2" type="fixed">
    <origin rpy="0 0 0" xyz="-0.0127 0.005 0.092"/>
    <parent link="l2_fLink"/>
    <child link="sa2_aLink"/>
  </joint>
  <link name="sa3_aLink">
    <inertial>
      <mass value="0.001"/>
      <inertia ixx="0.00012" ixy="0" ixz="0" iyy="0.00096" iyz="0" izz="0.00094"/>
    </inertial>
  </link>
  <!-- JOINT ACTUATOR - SCREW BASE -->
  <joint name="sa3_j_a_sb" type="fixed">
    <origin rpy="0 0 3.14159" xyz="-0.0045 -0.024 0.0107"/>
    <parent link="sa3_aLink"/>
    <child link="sa3_sbLink"/>
  </joint>
  <!-- INCLUDE SCREW BASE -->
  <link name="sa3_sbLink">
    <inertial>
      <mass value="0.2"/>
      <inertia ixx="0.064" ixy="0" ixz="0" iyy="0.064" iyz="0" izz="0.00024"/>
    </inertial>
    <!-- <collision name='collision_base'>
        <geometry>
            <cylinder>
                <radius>0.010</radius>
                <length>0.050</length>
              </cylinder>
        </geometry>
      </collision> -->
    <visual name="visual_base">
      <geometry>
        <mesh filename="file:///home/esther/robominers_ws/install/rm2_simulation/share/rm2_simulation/urdf/meshes/screw_base.dae"/>
      </geometry>
    </visual>
  </link>
  <!-- JOINT SCREW BASE - CW SCREW -->
  <joint name="sa3_j_sb_cws" type="continuous">
    <origin rpy="0 1.5708 0" xyz="0.010 0 0.0025"/>
    <parent link="sa3_sbLink"/>
    <child link="sa3_cwsLink"/>
    <axis rpy="0 0 0" xyz="0 0 1"/>
    <limit effort="500" velocity="3.141592653589793"/>
  </joint>
  <!-- INCLUDE CW SCREW -->
  <link name="sa3_cwsLink">
    <inertial>
      <mass value="0.2"/>
      <inertia ixx="0.064" ixy="0" ixz="0" iyy="0.064" iyz="0" izz="0.00024"/>
    </inertial>
    <!-- <collision name='collision_base'>
      <geometry>
          <cylinder>
              <radius>0.010</radius>
              <length>0.050</length>
            </cylinder>
      </geometry>
    </collision> -->
    <visual name="visual_base">
      <origin rpy="0 0 0" xyz="0.0 0.0 0.0406"/>
      <geometry>
        <mesh filename="file:///home/esther/robominers_ws/install/rm2_simulation/share/rm2_simulation/urdf/meshes/forward_screw.dae"/>
      </geometry>
    </visual>
  </link>
  <!-- JOINT SCREW BASE - CCW SCREW -->
  <joint name="sa3_j_sb_ccws" type="continuous">
    <origin rpy="0 -1.5708 0" xyz="-0.010 0 0.0025"/>
    <parent link="sa3_sbLink"/>
    <child link="sa3_ccwsLink"/>
    <axis rpy="0 0 0" xyz="0 0 1"/>
    <limit effort="500" velocity="3.141592653589793"/>
  </joint>
  <link name="sa3_ccwsLink">
    <inertial>
      <mass value="0.2"/>
      <inertia ixx="0.064" ixy="0" ixz="0" iyy="0.064" iyz="0" izz="0.00024"/>
    </inertial>
    <!-- <collision name='collision_base'>
          <geometry>
              <cylinder>
                  <radius>0.010</radius>
                  <length>0.050</length>
                </cylinder>
          </geometry>
        </collision> -->
    <visual name="visual_base">
      <origin rpy="0 0 0" xyz="0.0 0.0 0.0406"/>
      <geometry>
        <mesh filename="file:///home/esther/robominers_ws/install/rm2_simulation/share/rm2_simulation/urdf/meshes/backward_screw.dae"/>
      </geometry>
    </visual>
  </link>
  <!-- JOINT SIMPLE LEG 3 - SCREW ACTUATOR -->
  <joint name="j_l1_sa3" type="fixed">
    <origin rpy="0 0 0" xyz="-0.0127 0.005 0.092"/>
    <parent link="l3_fLink"/>
    <child link="sa3_aLink"/>
  </joint>
  <!-- =================================================================================== -->
  <!-- |                                          WHEELS                                 | -->
  <!-- =================================================================================== -->
  <!-- INCLUDE ACTUATOR LINK -->
  <link name="wa2_aLink">
    <inertial>
      <mass value="0.001"/>
      <inertia ixx="0.00012" ixy="0" ixz="0" iyy="0.00096" iyz="0" izz="0.00094"/>
    </inertial>
  </link>
  <!-- INCLUDE WHEELS BAR -->
  <link name="wa2_wbLink">
    <inertial>
      <mass value="0.2"/>
      <inertia ixx="0.064" ixy="0" ixz="0" iyy="0.064" iyz="0" izz="0.064"/>
    </inertial>
    <collision name="collision_base">
      <geometry>
        <cylinder length="0.08" radius="0.018"/>
      </geometry>
    </collision>
    <!-- <visual name='visual_base'>
                <geometry>
                    <cylinder length="0.08" radius="0.018" />
                </geometry>
                <material name="green">
                    <color rgba="0 1 0 1" />
                </material>
            </visual> -->
  </link>
  <!-- JOINT ACTUATOR - WHEELS BAR -->
  <joint name="wa2_j_a_wb" type="fixed">
    <origin rpy="0 1.5708 0" xyz="-0.0045 -0.024 0.0107"/>
    <parent link="wa2_aLink"/>
    <child link="wa2_wbLink"/>
  </joint>
  <!-- INCLUDE FRONT WHEEL -->
  <link name="wa2_fwLink">
    <inertial>
      <mass value="0.1"/>
      <inertia ixx="0.064" ixy="0" ixz="0" iyy="0.064" iyz="0" izz="0.064"/>
    </inertial>
    <collision name="collision_base">
      <geometry>
        <cylinder length="0.01" radius="0.03"/>
      </geometry>
    </collision>
    <!-- <visual name='visual_base'>
                <geometry>
                    <cylinder length="0.01" radius="0.03" />
                </geometry>
                <material name="red">
                    <color rgba="1 0 0 1" />
                </material>
            </visual> -->
  </link>
  <!-- JOINT WHEELS BAR - FRONT WHEEL -->
  <joint name="wa2_j_wb_fw" type="continuous">
    <origin rpy="1.5708 0 0" xyz="0.009 0 0.040"/>
    <parent link="wa2_wbLink"/>
    <child link="wa2_fwLink"/>
    <axis rpy="0 0 0" xyz="0 0 1"/>
    <limit effort="500" velocity="3.141592653589793"/>
  </joint>
  <!-- INCLUDE REAR WHEEL -->
  <link name="wa2_rwLink">
    <inertial>
      <mass value="0.1"/>
      <inertia ixx="0.064" ixy="0" ixz="0" iyy="0.064" iyz="0" izz="0.064"/>
    </inertial>
    <collision name="collision_base">
      <geometry>
        <cylinder length="0.01" radius="0.03"/>
      </geometry>
    </collision>
    <!-- <visual name='visual_base'>
                <geometry>
                    <cylinder length="0.01" radius="0.03" />
                </geometry>
                <material name="red">
                    <color rgba="1 0 0 1" />
                </material>
            </visual> -->
  </link>
  <!-- JOINT WHEELS BAR - REAR WHEEL -->
  <joint name="wa2_j_wb_rw" type="continuous">
    <origin rpy="1.5708 0 0" xyz="0.009 0 -0.040"/>
    <parent link="wa2_wbLink"/>
    <child link="wa2_rwLink"/>
    <axis rpy="0 0 0" xyz="0 0 1"/>
    <limit effort="500" velocity="3.141592653589793"/>
  </joint>
  <!-- JOINT SIMPLE LEG 2 - WHEELS ACTUATOR 2 (LEFT) -->
  <joint name="j_l12_wa2" type="fixed">
    <origin rpy="0 0 0" xyz="-0.0127 0.005 0.092"/>
    <parent link="l2_fLink"/>
    <child link="wa2_aLink"/>
  </joint>
</robot>
