<?xml version="1.0"?>
<sdf version="1.6">
  <world name="cave_world">
    <physics name="1ms" type="ignored">
      <max_step_size>0.001</max_step_size>
      <real_time_factor>1.0</real_time_factor>
    </physics>
    <plugin filename="libignition-gazebo-physics-system.so" name="ignition::gazebo::systems::Physics"></plugin>
    <plugin filename="libignition-gazebo-user-commands-system.so" name="ignition::gazebo::systems::UserCommands"></plugin>
    <plugin filename="libignition-gazebo-scene-broadcaster-system.so" name="ignition::gazebo::systems::SceneBroadcaster"></plugin>

    <!-- FLOOR -->
    <model name="ground_plane">
      <static>true</static>
      <pose>0 0 -0.115015 0 0 0</pose>
      <link name="link">
        <collision name="collision">
          <geometry>
            <plane>
              <normal>0 0 1</normal>
            </plane>
          </geometry>
        </collision>
        <visual name="visual">
          <geometry>
            <plane>
              <normal>0 0 1</normal>
              <size>100 100</size>
            </plane>
          </geometry>
          <material>
            <ambient>0.8 0.8 0.8 1</ambient>
            <diffuse>0.8 0.8 0.8 1</diffuse>
            <specular>0.8 0.8 0.8 1</specular>
          </material>
        </visual>
      </link>
    </model>

    <light type="directional" name="sun">
      <cast_shadows>true</cast_shadows>
      <pose>0 0 10 0 0 0</pose>
      <diffuse>0.8 0.8 0.8 1</diffuse>
      <specular>0.2 0.2 0.2 1</specular>
      <attenuation>
        <range>1000</range>
        <constant>0.9</constant>
        <linear>0.01</linear>
        <quadratic>0.001</quadratic>
      </attenuation>
      <direction>-0.5 0.1 -0.9</direction>
    </light>


    <!-- INCLUDE BODY-->
    <model name="rm2_body">
      <include>
        <pose>0 0 0 0 0 0</pose>
        <uri>model://rm2_body</uri>
      </include>
       <!-- INCLUDE LEG 1-->
      <include>
        <pose>-0.004511 0.000021 0.086269 0 0 0</pose>
        <uri>model://rm2_leg</uri>
        <name>rm2_leg_1</name>
      </include>
      <!-- JOINT BODY - LEG: error not nested files-->
     <joint name="leg_body_joint" type="revolute">

      <!--POSE JOINT></POSE>-->
        <parent>rm2_body::base</parent>
        <child>rm2_leg_1::leg_motors_structure</child>
        <axis>
          <xyz>1 0 0</xyz>
        </axis>
      </joint>
    </model>
    <!-- 
    <model name="cave">
      <include>
        <pose>0 0 0 0 0 0</pose>
        <uri>model://cave</uri>
        <name>cave</name>
      </include>
      </model>
-->

  </world>
</sdf>