<?xml version="1.0"?>
<sdf version="1.6">
  <world name="cave_world">
    <!--
    <gravity>0 0 -9.8</gravity>
    <static>false</static>
    <physics name="1ms" type="ode">
      <max_step_size>0.001</max_step_size>
      <real_time_factor>1.0</real_time_factor>
    </physics>
    -->
    <physics name="1ms" type="ignored">
      <max_step_size>0.001</max_step_size>
      <real_time_factor>1.0</real_time_factor>
    </physics>

    <plugin filename="libignition-gazebo-physics-system.so" name="ignition::gazebo::systems::Physics"></plugin>
    <plugin filename="libignition-gazebo-user-commands-system.so" name="ignition::gazebo::systems::UserCommands"></plugin>
    <plugin filename="libignition-gazebo-scene-broadcaster-system.so" name="ignition::gazebo::systems::SceneBroadcaster"></plugin>


    <!-- FLOOR -->
    <model name="ground_plane">
      <static>true</static>
      <pose>0 0 -0.115015 0 0 0</pose>
      <link name="link">
        <collision name="collision">
          <geometry>
            <plane>
              <normal>0 0 1</normal>
            </plane>
          </geometry>
        </collision>
        <visual name="visual">
          <geometry>
            <plane>
              <normal>0 0 1</normal>
              <size>100 100</size>
            </plane>
          </geometry>
          <material>
            <ambient>0.8 0.8 0.8 1</ambient>
            <diffuse>0.8 0.8 0.8 1</diffuse>
            <specular>0.8 0.8 0.8 1</specular>
          </material>
        </visual>
      </link>
    </model>

    <!-- SUN -->
    <light type="directional" name="sun">
      <cast_shadows>true</cast_shadows>
      <pose>0 0 10 0 0 0</pose>
      <diffuse>0.8 0.8 0.8 1</diffuse>
      <specular>0.2 0.2 0.2 1</specular>
      <attenuation>
        <range>1000</range>
        <constant>0.9</constant>
        <linear>0.01</linear>
        <quadratic>0.001</quadratic>
      </attenuation>
      <direction>-0.5 0.1 -0.9</direction>
    </light>

    <!-- INCLUDE BODY Y PATAS -->
    <model name="mod1">
      <include>
        <pose>0 0 0 0 0 0</pose>
        <uri>model://rm2_body</uri>
        <name>b</name>
      </include>

      <!-- INCLUDE LEG 1 -->
      <include>
        <pose relative_to="j_b_l1">-0.085512 0 0.011284 0 0 0</pose>
        <uri>model://rm2_leg</uri>
        <name>l1</name>
      </include>

      <!-- JOINT BODY - LEG 1 -->
      <joint name="j_b_l1" type="revolute">
        <pose relative_to="b::bodyLink">0.081 0 0.074985 0 0 0</pose>
        <parent>b::bodyLink</parent>
        <child>l1::legLink</child>
        <axis>
          <xyz>1 0 0</xyz>
          <limit>
            <lower>-1.041</lower>
            <upper>1.041</upper>
          </limit>
        </axis>
      </joint>

      <!-- MOVE JOINT BODY - LEG 1 -->
      <plugin filename="ignition-gazebo-joint-position-controller-system" name="ignition::gazebo::systems::JointPositionController">
        <joint_name>j_b_l1</joint_name>
        <topic>pos_j_l1</topic>
      </plugin>


      <!-- INCLUDE LEG 2 -->
      <include>
        <pose relative_to="j_b_l2">-0.085512 0 0.011284 0 0 0</pose>
        <uri>model://rm2_leg</uri>
        <name>l2</name>
      </include>

      <!-- JOINT BODY - LEG 2 -->
      <joint name="j_b_l2" type="revolute">
        <pose relative_to="b::bodyLink">0.081 0.064947 -0.037515 -2.09439510239 0 0</pose>
        <parent>b::bodyLink</parent>
        <child>l2::legLink</child>
        <axis>
          <xyz>1 0 0</xyz>
          <limit>
            <lower>-1.041</lower>
            <upper>1.041</upper>
          </limit>
        </axis>
      </joint>

      <!-- MOVE JOINT BODY - LEG 2 -->
      <plugin filename="ignition-gazebo-joint-position-controller-system" name="ignition::gazebo::systems::JointPositionController">
        <joint_name>j_b_l2</joint_name>
        <topic>pos_j_l2</topic>
      </plugin>
      <!-- INCLUDE LEG 3 -->
      <include>
        <pose relative_to="j_b_l3">-0.085512 0 0.011284 0 0 0</pose>
        <uri>model://rm2_leg</uri>
        <name>l3</name>
      </include>

      <!-- JOINT BODY - LEG 3 -->
      <joint name="j_b_l3" type="revolute">
        <pose relative_to="b::bodyLink">0.081 -0.064947 -0.037515 2.09439510239 0 0</pose>
        <parent>b::bodyLink</parent>
        <child>l3::legLink</child>
        <axis>
          <xyz>1 0 0</xyz>
          <limit>
            <lower>-1.041</lower>
            <upper>1.041</upper>
          </limit>
        </axis>
      </joint>

      <!-- MOVE JOINT BODY - LEG 3 -->
      <plugin filename="ignition-gazebo-joint-position-controller-system" name="ignition::gazebo::systems::JointPositionController">
        <joint_name>j_b_l3</joint_name>
        <topic>pos_j_l3</topic>
      </plugin>

            <!-- NO VA TODAVIA -->
            <plugin filename="ignition-gazebo-joint-position-controller-system" name="ignition::gazebo::systems::JointPositionController">
              <joint_name>l1:j_l_fm1</joint_name>
              <topic>pos_j_l1_fm1</topic>
            </plugin>
      
    </model>
  </world>
</sdf>