<?xml version="1.0"?>
<sdf version="1.7">
  <model name="leg">
    <link name='legLink'>
      <pose>0 0 0 0 0 0</pose>
      <inertial>
        <mass>0.6</mass>
        <inertia>
          <ixx>0.032</ixx>
          <ixy>0</ixy>
          <ixz>0</ixz>
          <iyy>0.032</iyy>
          <iyz>0</iyz>
          <izz>0.00012</izz>
        </inertia>
      </inertial>
      <collision name='collision'>
        <geometry>
          <box>
            <size>0.166 0.040 0.047</size>
          </box>
        </geometry>
      </collision>
      <visual name='visual'>

        <geometry>
          <mesh>
            <!-- <scale> 0.001 0.001 0.001</scale>-->
            <uri>model://rm2_leg/meshes/l_simple.dae</uri>
          </mesh>
        </geometry>

      </visual>
    </link>


    <!-- INCLUDE FRAME MOTOR 1 -->
    <link name="fm1Link">
      <pose relative_to="j_l_fm1">-0.013863 -0.019021 -0.01165 0 0 0</pose>
      <inertial>
        <mass>0.1</mass>
        <inertia>
          <ixx>0.032</ixx>
          <ixy>0</ixy>
          <ixz>0</ixz>
          <iyy>0.032</iyy>
          <iyz>0</iyz>
          <izz>0.00012</izz>
        </inertia>
      </inertial>
      <collision name='collision'>
        <geometry>
          <mesh>
            <scale> 0.001 0.001 0.001</scale>
            <uri>model://rm2_leg/meshes/fm1_collision.stl</uri>
          </mesh>
        </geometry>
      </collision>
      <visual name='visual'>
        <geometry>
          <mesh>
            <!-- <scale> 0.001 0.001 0.001</scale>-->
            <uri>model://rm2_leg/meshes/fm1_real.dae</uri>
          </mesh>
        </geometry>
       </visual>
    </link>

    <!-- JOINT LEG - FRAME MOTOR 1 -->
    <joint name="j_l_fm1" type="revolute">
      <pose relative_to="legLink">0.066412 0.019015 0.012752 0 0 0 </pose>
      <parent>legLink</parent>
      <child>fm1Link</child>
      <axis>
        <xyz>0 1 0</xyz>
      </axis>
    </joint>

    <!-- NO VA TODAVIA
            <plugin filename="ignition-gazebo-joint-position-controller-system" name="ignition::gazebo::systems::JointPositionController">
              <joint_name>l1:j_l_fm1</joint_name>
              <topic>pos_j_l1_fm1</topic>
            </plugin> -->


    <!-- INCLUDE FRAME MOTOR 2 -->
    <link name="fm2Link">
      <pose relative_to="j_l_fm2">0.013867 0.001149 -0.011636 0 0 0</pose>
      <inertial>
        <mass>0.1</mass>
        <inertia>
          <ixx>0.032</ixx>
          <ixy>0</ixy>
          <ixz>0</ixz>
          <iyy>0.032</iyy>
          <iyz>0</iyz>
          <izz>0.00012</izz>
        </inertia>
      </inertial>
      <collision name='collision'>
        <geometry>
          <mesh>
            <scale> 0.001 0.001 0.001</scale>
            <uri>model://rm2_leg/meshes/fm2_collision.stl</uri>
          </mesh>
        </geometry>
      </collision>
      <visual name='visual'>
        <geometry>
          <mesh>
            <!-- <scale> 0.001 0.001 0.001</scale>-->
            <uri>model://rm2_leg/meshes/fm2_real.dae</uri>
          </mesh>
        </geometry>
      </visual>
    </link>

    <!-- JOINT LEG - FRAME MOTOR 2 -->
    <joint name="j_l_fm2" type="revolute">
      <pose relative_to="legLink">-0.057399 0.018994 0.012734 0 0 0 </pose>
      <parent>legLink</parent>
      <child>fm2Link</child>
      <axis>
        <xyz>0 1 0</xyz>
      </axis>
    </joint>

    <!-- INCLUDE FRAME MOTOR 3 -->
    <link name="fm3Link">
      <pose relative_to="j_l_fm3">-0.013867 -0.001149 -0.011636 0 0 0</pose>
      <inertial>
        <mass>0.1</mass>
        <inertia>
          <ixx>0.032</ixx>
          <ixy>0</ixy>
          <ixz>0</ixz>
          <iyy>0.032</iyy>
          <iyz>0</iyz>
          <izz>0.00012</izz>
        </inertia>
      </inertial>
      <collision name='collision'>
        <geometry>
          <mesh>
            <scale> 0.001 0.001 0.001</scale>
            <uri>model://rm2_leg/meshes/fm3_collision.stl</uri>
          </mesh>
        </geometry>
      </collision>
      <visual name='visual'>
        <geometry>
          <mesh>
            <!-- <scale> 0.001 0.001 0.001</scale>-->
            <uri>model://rm2_leg/meshes/fm3_real.dae</uri>
          </mesh>
        </geometry>
      </visual>
    </link>

    <!-- JOINT LEG - FRAME MOTOR 3 -->
    <joint name="j_l_fm3" type="revolute">
      <pose relative_to="legLink">-0.012388 -0.019006 0.012734 0 0 0 </pose>
      <parent>legLink</parent>
      <child>fm3Link</child>
      <axis>
        <xyz>0 1 0</xyz>
      </axis>
    </joint>

    <!-- INCLUDE FRAME ACTUATOR 1 -->
    <link name="fa1Link">
      <pose relative_to="j_fm1_fa1">0.009816 -0.0210 0.028349 0 0</pose>
      <inertial>
        <mass>0.1</mass>
        <inertia>
          <ixx>0.032</ixx>
          <ixy>0</ixy>
          <ixz>0</ixz>
          <iyy>0.032</iyy>
          <iyz>0</iyz>
          <izz>0.00012</izz>
        </inertia>
      </inertial>
      <collision name='collision'>
        <geometry>
          <mesh>
            <scale> 0.001 0.001 0.001</scale>
            <uri>model://rm2_leg/meshes/fa1_collision.stl</uri>
          </mesh>
        </geometry>
      </collision>
      <visual name='visual'>

        <geometry>
          <mesh>
            <!-- <scale> 0.001 0.001 0.001</scale>-->
            <uri>model://rm2_leg/meshes/fa1_real.dae</uri>
          </mesh>
        </geometry>
      </visual>
    </link>

    <!-- JOINT FRAME MOTOR 1 - FRAME ACTUATOR 1 -->
    <joint name="j_fm1_fa1" type="revolute">
      <pose relative_to="fm1Link"> -0.028265 0.021 -0.023721 0 0 0 </pose>
      <parent>fm1Link</parent>
      <child>fa1Link</child>
      <axis>
        <xyz>0 1 0</xyz>
      </axis>
    </joint>

    <!-- INCLUDE FRAME ACTUATOR 2 -->
    <link name="fa2Link">
      <pose relative_to="j_fm2_fa2">-0.009816 0.0015 0.028349 0 0</pose>
      <inertial>
        <mass>0.1</mass>
        <inertia>
          <ixx>0.032</ixx>
          <ixy>0</ixy>
          <ixz>0</ixz>
          <iyy>0.032</iyy>
          <iyz>0</iyz>
          <izz>0.00012</izz>
        </inertia>
      </inertial>
      <collision name='collision'>
        <geometry>
          <mesh>
            <scale> 0.001 0.001 0.001</scale>
            <uri>model://rm2_leg/meshes/fa2_collision.stl</uri>
          </mesh>
        </geometry>
      </collision>
      <visual name='visual'>

        <geometry>
          <mesh>
            <!-- <scale> 0.001 0.001 0.001</scale>-->
            <uri>model://rm2_leg/meshes/fa2_real.dae</uri>
          </mesh>
        </geometry>
      </visual>
    </link>

    <!-- JOINT FRAME MOTOR 2 - FRAME ACTUATOR 2 -->
    <joint name="j_fm2_fa2" type="revolute">
      <pose relative_to="fm2Link"> 0.028265 0.000851 -0.023717 0 0 0 </pose>
      <parent>fm2Link</parent>
      <child>fa2Link</child>
      <axis>
        <xyz>0 1 0</xyz>
      </axis>
    </joint>

    <!-- INCLUDE FRAME ACTUATOR 3 -->
    <link name="fa3Link">
      <pose relative_to="j_fm3_fa3">0.009816 -0.0015 0.028349 0 0</pose>
      <inertial>
        <mass>0.1</mass>
        <inertia>
          <ixx>0.032</ixx>
          <ixy>0</ixy>
          <ixz>0</ixz>
          <iyy>0.032</iyy>
          <iyz>0</iyz>
          <izz>0.00012</izz>
        </inertia>
      </inertial>
      <collision name='collision'>
        <geometry>
          <mesh>
            <scale> 0.001 0.001 0.001</scale>
            <uri>model://rm2_leg/meshes/fa3_collision.stl</uri>
          </mesh>
        </geometry>
      </collision>
      <visual name='visual'>
        <geometry>
          <mesh>
            <!-- <scale> 0.001 0.001 0.001</scale>-->
            <uri>model://rm2_leg/meshes/fa3_real.dae</uri>
          </mesh>
        </geometry>
      </visual>
    </link>

    <!-- JOINT FRAME MOTOR 3 - FRAME ACTUATOR 3 -->
    <joint name="j_fm3_fa3" type="revolute">
      <pose relative_to="fm3Link"> -0.028265 -0.000851 -0.023717 0 0 0 </pose>
      <parent>fm3Link</parent>
      <child>fa3Link</child>
      <axis>
        <xyz>0 1 0</xyz>
      </axis>
    </joint>

    <!-- INCLUDE ACTUATOR 
    <link name="aLink">
      <pose relative_to="j_a_fa1">-0.039354 -0.024243 0.012507 0 0</pose>
      <inertial>
        <mass>0.1</mass>
        <inertia>
          <ixx>0.032</ixx>
          <ixy>0</ixy>
          <ixz>0</ixz>
          <iyy>0.032</iyy>
          <iyz>0</iyz>
          <izz>0.00012</izz>
        </inertia>
      </inertial>
      <collision name='collision'>
        <pose>0 0 0 0 1.57 0</pose>
        <geometry>
          <cylinder>
            <radius>0.42</radius>
            <lenght>0.215</lenght>
          </cylinder>
        </geometry>
      </collision>
      <visual name='visual'>
        <pose>0 0 0 0 1.57 0</pose>
        <geometry>
          <cylinder>
            <radius>0.42</radius>
            <lenght>0.215</lenght>
          </cylinder>
        </geometry>
      </visual>
    </link>-->

    <!-- JOINT ACTUATOR - FRAME ACTUATOR 1 
    <joint name="j_a_fa1" type="fixed">
      <pose relative_to="fa1Link"> 0.009816 0.024 0.028349 0 0 0 </pose>
      <parent>fa1Link</parent>
      <child>aLink</child>
      <axis>
        <xyz>0 1 0</xyz>
      </axis>
    </joint> -->

    <!-- JOINT ACTUATOR - FRAME ACTUATOR 2 
    <joint name="j_a_fa2" type="fixed">
      <pose relative_to="fa2Link"> -0.009816 0.0015 0.028349 0 </pose>
      <parent>fa2Link</parent>
      <child>aLink</child>
      <axis>
        <xyz>0 1 0</xyz>
      </axis>
    </joint>-->

    <!-- JOINT ACTUATOR - FRAME ACTUATOR 3
    <joint name="j_a_fa3" type="fixed">
      <pose relative_to="fa3Link"> 0.009816 -0.0015 0.028349 0 0 0 </pose>
      <parent>fa3Link</parent>
      <child>aLink</child>
      <axis>
        <xyz>0 1 0</xyz>
      </axis>
    </joint>  -->

  </model>
</sdf>